telegram.vendor.ptb_urllib3.urllib3.connectionpool - WARNING - Retrying (Retry(total=2, connect=None, read=None, redirect=None)) after connection broken by 'ConnectTimeoutError(<telegram.vendor.ptb_urllib3.urllib3.contrib.socks.SOCKSHTTPSConnection object at 0x10925cfd0>, 'Connection to api.telegram.org timed out. (connect timeout=5.0)')': /bot753185034:AAFp2AC87A3HxQjl7bsfifedB_78rE4et-0/getUpdates
telegram.vendor.ptb_urllib3.urllib3.connectionpool - WARNING - Retrying (Retry(total=2, connect=None, read=None, redirect=None)) after connection broken by 'ConnectTimeoutError(<telegram.vendor.ptb_urllib3.urllib3.contrib.socks.SOCKSHTTPSConnection object at 0x109239fd0>, 'Connection to api.telegram.org timed out. (connect timeout=5.0)')': /bot753185034:AAFp2AC87A3HxQjl7bsfifedB_78rE4et-0/getUpdates
telegram.ext.dispatcher - ERROR - An uncaught error was raised while processing the update
Traceback (most recent call last):
  File "/Library/Frameworks/Python.framework/Versions/3.6/lib/python3.6/site-packages/telegram/ext/dispatcher.py", line 279, in process_update
    handler.handle_update(update, self)
  File "/Library/Frameworks/Python.framework/Versions/3.6/lib/python3.6/site-packages/telegram/ext/commandhandler.py", line 173, in handle_update
    return self.callback(dispatcher.bot, update, **optional_args)
  File "bot_planet.py", line 24, in print_new_planet
    var_planet = user_text.split(' ')[1]
IndexError: list index out of range
telegram.vendor.ptb_urllib3.urllib3.connectionpool - WARNING - Retrying (Retry(total=2, connect=None, read=None, redirect=None)) after connection broken by 'ConnectTimeoutError(<telegram.vendor.ptb_urllib3.urllib3.contrib.socks.SOCKSHTTPSConnection object at 0x104deae80>, 'Connection to api.telegram.org timed out. (connect timeout=5.0)')': /bot753185034:AAFp2AC87A3HxQjl7bsfifedB_78rE4et-0/getUpdates
telegram.vendor.ptb_urllib3.urllib3.connectionpool - WARNING - Retrying (Retry(total=2, connect=None, read=None, redirect=None)) after connection broken by 'ConnectTimeoutError(<telegram.vendor.ptb_urllib3.urllib3.contrib.socks.SOCKSHTTPSConnection object at 0x10b1dc7b8>, 'Connection to api.telegram.org timed out. (connect timeout=5.0)')': /bot753185034:AAFp2AC87A3HxQjl7bsfifedB_78rE4et-0/getUpdates
telegram.vendor.ptb_urllib3.urllib3.connectionpool - WARNING - Retrying (Retry(total=2, connect=None, read=None, redirect=None)) after connection broken by 'ConnectTimeoutError(<telegram.vendor.ptb_urllib3.urllib3.contrib.socks.SOCKSHTTPSConnection object at 0x10b093518>, 'Connection to api.telegram.org timed out. (connect timeout=5.0)')': /bot753185034:AAFp2AC87A3HxQjl7bsfifedB_78rE4et-0/getUpdates
telegram.vendor.ptb_urllib3.urllib3.connectionpool - WARNING - Retrying (Retry(total=2, connect=None, read=None, redirect=None)) after connection broken by 'ConnectTimeoutError(<telegram.vendor.ptb_urllib3.urllib3.contrib.socks.SOCKSHTTPSConnection object at 0x103681d30>, 'Connection to api.telegram.org timed out. (connect timeout=5.0)')': /bot753185034:AAFp2AC87A3HxQjl7bsfifedB_78rE4et-0/getUpdates
telegram.vendor.ptb_urllib3.urllib3.connectionpool - WARNING - Retrying (Retry(total=2, connect=None, read=None, redirect=None)) after connection broken by 'ConnectTimeoutError(<telegram.vendor.ptb_urllib3.urllib3.contrib.socks.SOCKSHTTPSConnection object at 0x104be0da0>, 'Connection to api.telegram.org timed out. (connect timeout=5.0)')': /bot753185034:AAFp2AC87A3HxQjl7bsfifedB_78rE4et-0/getUpdates
telegram.ext.dispatcher - ERROR - An uncaught error was raised while processing the update
Traceback (most recent call last):
  File "/Library/Frameworks/Python.framework/Versions/3.6/lib/python3.6/site-packages/telegram/ext/dispatcher.py", line 279, in process_update
    handler.handle_update(update, self)
  File "/Library/Frameworks/Python.framework/Versions/3.6/lib/python3.6/site-packages/telegram/ext/commandhandler.py", line 173, in handle_update
    return self.callback(dispatcher.bot, update, **optional_args)
  File "bot_planet.py", line 38, in print_new_planet
    m = ephem.planet_name('2019')
AttributeError: module 'ephem' has no attribute 'planet_name'
telegram.vendor.ptb_urllib3.urllib3.connectionpool - WARNING - Retrying (Retry(total=2, connect=None, read=None, redirect=None)) after connection broken by 'ConnectTimeoutError(<telegram.vendor.ptb_urllib3.urllib3.contrib.socks.SOCKSHTTPSConnection object at 0x106b696a0>, 'Connection to api.telegram.org timed out. (connect timeout=5.0)')': /bot753185034:AAFp2AC87A3HxQjl7bsfifedB_78rE4et-0/getUpdates
telegram.vendor.ptb_urllib3.urllib3.connectionpool - WARNING - Retrying (Retry(total=2, connect=None, read=None, redirect=None)) after connection broken by 'ConnectTimeoutError(<telegram.vendor.ptb_urllib3.urllib3.contrib.socks.SOCKSHTTPSConnection object at 0x106b694e0>, 'Connection to api.telegram.org timed out. (connect timeout=5.0)')': /bot753185034:AAFp2AC87A3HxQjl7bsfifedB_78rE4et-0/getUpdates
telegram.vendor.ptb_urllib3.urllib3.connectionpool - WARNING - Retrying (Retry(total=2, connect=None, read=None, redirect=None)) after connection broken by 'ConnectTimeoutError(<telegram.vendor.ptb_urllib3.urllib3.contrib.socks.SOCKSHTTPSConnection object at 0x106f9b908>, 'Connection to api.telegram.org timed out. (connect timeout=5.0)')': /bot753185034:AAFp2AC87A3HxQjl7bsfifedB_78rE4et-0/getUpdates
telegram.vendor.ptb_urllib3.urllib3.connectionpool - WARNING - Retrying (Retry(total=2, connect=None, read=None, redirect=None)) after connection broken by 'ConnectTimeoutError(<telegram.vendor.ptb_urllib3.urllib3.contrib.socks.SOCKSHTTPSConnection object at 0x106b69d30>, 'Connection to api.telegram.org timed out. (connect timeout=5.0)')': /bot753185034:AAFp2AC87A3HxQjl7bsfifedB_78rE4et-0/getUpdates
telegram.vendor.ptb_urllib3.urllib3.connectionpool - WARNING - Retrying (Retry(total=2, connect=None, read=None, redirect=None)) after connection broken by 'ConnectTimeoutError(<telegram.vendor.ptb_urllib3.urllib3.contrib.socks.SOCKSHTTPSConnection object at 0x109058d68>, 'Connection to api.telegram.org timed out. (connect timeout=5.0)')': /bot753185034:AAFp2AC87A3HxQjl7bsfifedB_78rE4et-0/getUpdates
telegram.vendor.ptb_urllib3.urllib3.connectionpool - WARNING - Retrying (Retry(total=2, connect=None, read=None, redirect=None)) after connection broken by 'ConnectTimeoutError(<telegram.vendor.ptb_urllib3.urllib3.contrib.socks.SOCKSHTTPSConnection object at 0x109077080>, 'Connection to api.telegram.org timed out. (connect timeout=5.0)')': /bot753185034:AAFp2AC87A3HxQjl7bsfifedB_78rE4et-0/getUpdates
